<robot name="6dof-arm">

	<link name="base_link">
		<visual>
			<origin xyz="0 0 0" rpy="0 0 0"/>
			<geometry>
				<mesh filename="meshes/base_link.dae"/>
			</geometry>
		</visual>
	</link>
	
	<link name="k0">
		<visual>
			<origin xyz="0 0 0" rpy="0 0 0"/>
			<geometry>
				<mesh filename="meshes/link01.dae"/>
			</geometry>
		</visual>
	</link>
	
	<link name="k1">
		<visual>
			<origin xyz="0 0 0" rpy="1.570796 0 -1.570796"/>
			<geometry>
				<mesh filename="meshes/link02.dae"/>
			</geometry>
		</visual>
	</link>
	
	<link name="k2">
		<visual>
			<origin xyz="0 0 0" rpy="0 -1.570796 0"/>
			<geometry>
				<mesh filename="meshes/link03.dae"/>
			</geometry>
		</visual>
	</link>
	
	<link name="k3">
		<visual>
			<origin xyz="0 0 0" rpy="1.570796 0 0"/>
			<geometry>
				<mesh filename="meshes/link04.dae"/>
			</geometry>
		</visual>
	</link>
	
	<link name="k4">
		<visual>
			<origin xyz="0 0 0" rpy="1.570796 0 0"/>
			<geometry>
				<mesh filename="meshes/link05.dae"/>
			</geometry>
		</visual>
	</link>
	
	<link name="k5">
		<visual>
			<origin xyz="0 0 0" rpy="1.570796 0 0"/>
			<geometry>
				<mesh filename="meshes/end_effector.dae"/>
			</geometry>
		</visual>
	</link>
	
	<joint name="j0" type="revolute">
		<origin xyz="0.000 0.000 0.000" rpy="0.00 0.00 0.00"/>
		<parent link="base_link"/>
		<child link="k0"/>
		<axis xyz="0 0 1"/> 
		<limit lower="-3.14" upper="3.14" />
	</joint>
	
	<joint name="j1" type="revolute">
		<origin xyz="0.092 -0.160 0.120" rpy="0.00 0.00 0.00"/>
		<parent link="k0"/>
		<child link="k1"/>
		<axis xyz="1 0 0"/>
		<limit lower="0" upper="3.14" />
	</joint>
	
	<joint name="j2" type="revolute">
		<origin xyz="0.000 0.300 0.000" rpy="0.00 0.00 0.00"/>
		<parent link="k1"/>
		<child link="k2"/>
		<axis xyz="-1 0 0"/>
		<limit lower="0" upper="2" />
	</joint>
	
	<joint name="j3" type="revolute">
		<origin xyz="-0.092 -0.080 0.104" rpy="0.00 0.00 0.00"/>
		<parent link="k2"/>
		<child link="k3"/>
		<axis xyz="0 1 0"/>
		<limit lower="-3.14" upper="3.14" />
	</joint>
	
	<joint name="j4" type="revolute">
		<origin xyz="0.00 -0.202 0.00" rpy="0.00 0.00 0.00"/>
		<parent link="k3"/>
		<child link="k4"/>
		<axis xyz="1 0 0"/>
		<limit lower="-1.57" upper="1.57" />
	</joint>
	
	<joint name="j5" type="revolute">
		<origin xyz="0.00 -0.062 0.00" rpy="0.00 0.00 0.00"/>
		<parent link="k4"/>
		<child link="k5"/>
		<axis xyz="0 1 0"/>
		<limit lower="-3.14" upper="3.14" />
	</joint>
</robot>